Workbook

Sheet Home
B2: SISTEMA DE GESTÃO DA RESIDÊNCIA MULTIPROFISSIONAL
B4: Modelo profissional em Excel sem macros • banco de dados único + dashboards
B6: Módulo | C6: Finalidade | D6: Como usar
B7: Cadastro | C7: Registrar residentes | D7: Preencha Nome, Profissão, Período, Ano e Situação. A CH é automática.
B8: Preceptores | C8: Cadastrar preceptores | D8: Use estes nomes na lista suspensa da Frequência.
B9: Cenários | C9: Cadastrar cenários de prática | D9: Use estes cenários na lista suspensa da Frequência.
B10: Frequencia | C10: Registrar ponto e atividades | D10: Lance cada ocorrência em uma linha; as horas são calculadas automaticamente.
B11: Dashboard | C11: Acompanhar indicadores | D11: Painel geral da turma e por residente.
B12: Relatorio_Individual | C12: Resumo individual | D12: Escolha o residente no topo e imprima o relatório.
B14: Observação: este arquivo foi construído sem macros para evitar bloqueios de segurança do Excel. As fórmulas foram mantidas em padrão nativo do .xlsx; ao abrir no Excel em português, o programa localiza separadores e formatos automaticamente.

Sheet Configurações
A1: CONFIGURAÇÕES E LISTAS SUSPENSAS
A3: Profissões | B3: Período | C3: Ano | D3: Situação | E3: Tipo de registro | F3: Mês | H3: Parâmetro | I3: Valor
A4: Enfermagem | B4: R1 | C4: 2026 | D4: ATIVO | E4: Prática | F4: Janeiro | H4: CH total do programa | I4: 5760
A5: Farmácia | B5: R2 | C5: 2027 | D5: INATIVO | E5: Teórica | F5: Fevereiro | H5: CH anual | I5: 2880
A6: Fisioterapia | C6: 2028 | D6: FÉRIAS | E6: Teórico-prática | F6: Março | H6: CH teórica anual | I6: 576
A7: Nutrição | D7: LICENÇA | E7: Ausência justificada | F7: Abril | H7: CH prática anual | I7: 2304
A8: Psicologia | D8: AFASTADO | E8: Falta | F8: Maio | H8: CH teórica total | I8: 1152
A9: Assistente Social | D9: TRANCADO | E9: Férias | F9: Junho | H9: CH prática total | I9: 4608
A10: Fonoaudiologia | D10: CONCLUÍDO | E10: Licença | F10: Julho
A11: Odontologia | D11: DESLIGADO | F11: Agosto
F12: Setembro
F13: Outubro
F14: Novembro
F15: Dezembro

Sheet Cadastro
A1: CADASTRO DOS RESIDENTES
A3: Nº | B3: Nome | C3: Profissão | D3: Período | E3: Ano | F3: Situação | G3: CH Programa | H3: CH Anual | I3: Observações
A4: 1 | B4: Daniely Kunrath | C4: Enfermagem | D4: R1 | E4: 2026 | F4: ATIVO | G4: =Configurações!$I$4 -> 5760 | H4: =Configurações!$I$5 -> 2880
A5: 2 | B5: Betânia Pereira Pardinho | C5: Enfermagem | D5: R1 | E5: 2026 | F5: ATIVO | G5: =Configurações!$I$4 -> 5760 | H5: =Configurações!$I$5 -> 2880
A6: 3 | B6: Paulo Fernandes Dos Santos | C6: Farmácia | D6: R1 | E6: 2026 | F6: ATIVO | G6: =Configurações!$I$4 -> 5760 | H6: =Configurações!$I$5 -> 2880
A7: 4 | B7: Maria Neves Lopes Menezes | C7: Fisioterapia | D7: R1 | E7: 2026 | F7: ATIVO | G7: =Configurações!$I$4 -> 5760 | H7: =Configurações!$I$5 -> 2880
A8: 5 | B8: Benedito Tales Santos Sousa | C8: Nutrição | D8: R1 | E8: 2026 | F8: ATIVO | G8: =Configurações!$I$4 -> 5760 | H8: =Configurações!$I$5 -> 2880
A9: 6 | B9: Andrea Raissa Bonfim Medeiros | C9: Odontologia | D9: R1 | E9: 2026 | F9: ATIVO | G9: =Configurações!$I$4 -> 5760 | H9: =Configurações!$I$5 -> 2880
A10: 7 | B10: Fabiana Martins Vieira | C10: Odontologia | D10: R1 | E10: 2026 | F10: ATIVO | G10: =Configurações!$I$4 -> 5760 | H10: =Configurações!$I$5 -> 2880
A11: 8 | B11: Pamela Daniele De Sousa | C11: Psicologia | D11: R1 | E11: 2026 | F11: ATIVO | G11: =Configurações!$I$4 -> 5760 | H11: =Configurações!$I$5 -> 2880
A12: 9 | B12: Marcia Sales Belfort | C12: Assistente Social | D12: R1 | E12: 2026 | F12: ATIVO | G12: =Configurações!$I$4 -> 5760 | H12: =Configurações!$I$5 -> 2880
G13: =Configurações!$I$4 -> 5760 | H13: =Configurações!$I$5 -> 2880
G14: =Configurações!$I$4 -> 5760 | H14: =Configurações!$I$5 -> 2880
G15: =Configurações!$I$4 -> 5760 | H15: =Configurações!$I$5 -> 2880
G16: =Configurações!$I$4 -> 5760 | H16: =Configurações!$I$5 -> 2880
G17: =Configurações!$I$4 -> 5760 | H17: =Configurações!$I$5 -> 2880
G18: =Configurações!$I$4 -> 5760 | H18: =Configurações!$I$5 -> 2880
G19: =Configurações!$I$4 -> 5760 | H19: =Configurações!$I$5 -> 2880
G20: =Configurações!$I$4 -> 5760 | H20: =Configurações!$I$5 -> 2880
G21: =Configurações!$I$4 -> 5760 | H21: =Configurações!$I$5 -> 2880
G22: =Configurações!$I$4 -> 5760 | H22: =Configurações!$I$5 -> 2880
G23: =Configurações!$I$4 -> 5760 | H23: =Configurações!$I$5 -> 2880
G24: =Configurações!$I$4 -> 5760 | H24: =Configurações!$I$5 -> 2880
... G100: =Configurações!$I$4 -> 5760 | H100: =Configurações!$I$5 -> 2880

Sheet Preceptores
A1: CADASTRO DE PRECEPTORES
A3: Nome | B3: Profissão | C3: Cenário principal | D3: E-mail | E3: Telefone
A4: Lidiane | B4: Enfermagem | C4: UBS
A5: Larissa | B5: Farmácia | C5: UBS
A6: Daniele | B6: Fisioterapia | C6: eMulti
A7: Soneli | B7: Nutrição | C7: UBS
A8: Ana Paula | B8: Psicologia | C8: CAPS
A9: Francielle | B9: Odontologia | C9: UBS
A10: Elaine | B10: Assistente Social | C10: Gestão
A11: Brendo | B11: Odontologia | C11: UBS

Sheet Cenários
A1: CENÁRIOS DE PRÁTICA
A3: Cenário | B3: Tipo | C3: Observações
A4: eMulti | B4: Atenção Primária
A5: eMulti/SAD | B5: Atenção Primária
A6: UBS Central | B6: Atenção Primária
A7: UBS setor 4 | B7: Atenção Primária
A8: UBS setor 7 | B8: Atenção Primária
A9: UBS setor 8 | B9: Atenção Primária
A10: UBS São Gabriel | B10: Atenção Primária
A11: Farmácia Municipal | B11: Atenção Primária
A12: CAPS | B12: Atenção Psicossocial
A13: Gestão | B13: Gestão em Saúde
A14: Vigilância em Saúde | B14: Vigilância
A15: Escola | B15: Intersetorial
A16: Comunidade | B16: Território

Sheet Frequencia
A1: FREQUÊNCIA GERAL DOS RESIDENTES - BANCO DE DADOS ÚNICO
A3: Data | B3: Ano | C3: Mês | D3: Residente | E3: Profissão | F3: Período | G3: Cenário | H3: Preceptor | I3: Tipo | J3: Entrada manhã | K3: Saída manhã | L3: Entrada tarde | M3: Saída tarde | N3: Entrada noite | O3: Saída noite | P3: Horas do dia | Q3: CH prática | R3: CH teórica
A4: 46082 | B4: =IF(A4="","",YEAR(A4)) -> 2026 | C4: =IF(A4="","",TEXT(A4,"mmmm")) -> março | D4: Daniely Kunrath | E4: =IFERROR(VLOOKUP(D4,Cadastro!$B$4:$H$100,2,FALSE),"") -> Enfermagem | F4: =IFERROR(VLOOKUP(D4,Cadastro!$B$4:$H$100,3,FALSE),"") -> R1 | G4: UBS Central | H4: Lidiane | I4: Prática | P4: =IF(OR(J4="",K4=""),0,(K4-J4)*24)+IF(OR(L4="",M4=""),0,(M4-L4)*24)+IF(OR(N4="",O4=""),0,(O4-N4)*24) -> 0 | Q4: =IF(OR(I4="Prática",I4="Teórico-prática"),P4,0) -> 0 | R4: =IF(OR(I4="Teórica",I4="Teórico-prática"),P4,0) -> 0
A5: 46083 | B5: =IF(A5="","",YEAR(A5)) -> 2026 | C5: =IF(A5="","",TEXT(A5,"mmmm")) -> março | D5: Daniely Kunrath | E5: =IFERROR(VLOOKUP(D5,Cadastro!$B$4:$H$100,2,FALSE),"") -> Enfermagem | F5: =IFERROR(VLOOKUP(D5,Cadastro!$B$4:$H$100,3,FALSE),"") -> R1 | G5: UBS Central | H5: Lidiane | I5: Prática | P5: =IF(OR(J5="",K5=""),0,(K5-J5)*24)+IF(OR(L5="",M5=""),0,(M5-L5)*24)+IF(OR(N5="",O5=""),0,(O5-N5)*24) -> 0 | Q5: =IF(OR(I5="Prática",I5="Teórico-prática"),P5,0) -> 0 | R5: =IF(OR(I5="Teórica",I5="Teórico-prática"),P5,0) -> 0
A6: 46084 | B6: =IF(A6="","",YEAR(A6)) -> 2026 | C6: =IF(A6="","",TEXT(A6,"mmmm")) -> março | D6: Daniely Kunrath | E6: =IFERROR(VLOOKUP(D6,Cadastro!$B$4:$H$100,2,FALSE),"") -> Enfermagem | F6: =IFERROR(VLOOKUP(D6,Cadastro!$B$4:$H$100,3,FALSE),"") -> R1 | G6: UBS Central | H6: Lidiane | I6: Prática | P6: =IF(OR(J6="",K6=""),0,(K6-J6)*24)+IF(OR(L6="",M6=""),0,(M6-L6)*24)+IF(OR(N6="",O6=""),0,(O6-N6)*24) -> 0 | Q6: =IF(OR(I6="Prática",I6="Teórico-prática"),P6,0) -> 0 | R6: =IF(OR(I6="Teórica",I6="Teórico-prática"),P6,0) -> 0
A7: 46085 | B7: =IF(A7="","",YEAR(A7)) -> 2026 | C7: =IF(A7="","",TEXT(A7,"mmmm")) -> março | D7: Daniely Kunrath | E7: =IFERROR(VLOOKUP(D7,Cadastro!$B$4:$H$100,2,FALSE),"") -> Enfermagem | F7: =IFERROR(VLOOKUP(D7,Cadastro!$B$4:$H$100,3,FALSE),"") -> R1 | G7: UBS Central | H7: Lidiane | I7: Prática | P7: =IF(OR(J7="",K7=""),0,(K7-J7)*24)+IF(OR(L7="",M7=""),0,(M7-L7)*24)+IF(OR(N7="",O7=""),0,(O7-N7)*24) -> 0 | Q7: =IF(OR(I7="Prática",I7="Teórico-prática"),P7,0) -> 0 | R7: =IF(OR(I7="Teórica",I7="Teórico-prática"),P7,0) -> 0
A8: 46086 | B8: =IF(A8="","",YEAR(A8)) -> 2026 | C8: =IF(A8="","",TEXT(A8,"mmmm")) -> março | D8: Daniely Kunrath | E8: =IFERROR(VLOOKUP(D8,Cadastro!$B$4:$H$100,2,FALSE),"") -> Enfermagem | F8: =IFERROR(VLOOKUP(D8,Cadastro!$B$4:$H$100,3,FALSE),"") -> R1 | G8: UBS Central | H8: Lidiane | I8: Prática | P8: =IF(OR(J8="",K8=""),0,(K8-J8)*24)+IF(OR(L8="",M8=""),0,(M8-L8)*24)+IF(OR(N8="",O8=""),0,(O8-N8)*24) -> 0 | Q8: =IF(OR(I8="Prática",I8="Teórico-prática"),P8,0) -> 0 | R8: =IF(OR(I8="Teórica",I8="Teórico-prática"),P8,0) -> 0
A9: 46087 | B9: =IF(A9="","",YEAR(A9)) -> 2026 | C9: =IF(A9="","",TEXT(A9,"mmmm")) -> março | D9: Daniely Kunrath | E9: =IFERROR(VLOOKUP(D9,Cadastro!$B$4:$H$100,2,FALSE),"") -> Enfermagem | F9: =IFERROR(VLOOKUP(D9,Cadastro!$B$4:$H$100,3,FALSE),"") -> R1 | G9: UBS Central | H9: Lidiane | I9: Prática | P9: =IF(OR(J9="",K9=""),0,(K9-J9)*24)+IF(OR(L9="",M9=""),0,(M9-L9)*24)+IF(OR(N9="",O9=""),0,(O9-N9)*24) -> 0 | Q9: =IF(OR(I9="Prática",I9="Teórico-prática"),P9,0) -> 0 | R9: =IF(OR(I9="Teórica",I9="Teórico-prática"),P9,0) -> 0
A10: 46088 | B10: =IF(A10="","",YEAR(A10)) -> 2026 | C10: =IF(A10="","",TEXT(A10,"mmmm")) -> março | D10: Daniely Kunrath | E10: =IFERROR(VLOOKUP(D10,Cadastro!$B$4:$H$100,2,FALSE),"") -> Enfermagem | F10: =IFERROR(VLOOKUP(D10,Cadastro!$B$4:$H$100,3,FALSE),"") -> R1 | G10: UBS Central | H10: Lidiane | I10: Prática | P10: =IF(OR(J10="",K10=""),0,(K10-J10)*24)+IF(OR(L10="",M10=""),0,(M10-L10)*24)+IF(OR(N10="",O10=""),0,(O10-N10)*24) -> 0 | Q10: =IF(OR(I10="Prática",I10="Teórico-prática"),P10,0) -> 0 | R10: =IF(OR(I10="Teórica",I10="Teórico-prática"),P10,0) -> 0
A11: 46089 | B11: =IF(A11="","",YEAR(A11)) -> 2026 | C11: =IF(A11="","",TEXT(A11,"mmmm")) -> março | D11: Daniely Kunrath | E11: =IFERROR(VLOOKUP(D11,Cadastro!$B$4:$H$100,2,FALSE),"") -> Enfermagem | F11: =IFERROR(VLOOKUP(D11,Cadastro!$B$4:$H$100,3,FALSE),"") -> R1 | G11: UBS Central | H11: Lidiane | I11: Prática | P11: =IF(OR(J11="",K11=""),0,(K11-J11)*24)+IF(OR(L11="",M11=""),0,(M11-L11)*24)+IF(OR(N11="",O11=""),0,(O11-N11)*24) -> 0 | Q11: =IF(OR(I11="Prática",I11="Teórico-prática"),P11,0) -> 0 | R11: =IF(OR(I11="Teórica",I11="Teórico-prática"),P11,0) -> 0
A12: 46090 | B12: =IF(A12="","",YEAR(A12)) -> 2026 | C12: =IF(A12="","",TEXT(A12,"mmmm")) -> março | D12: Daniely Kunrath | E12: =IFERROR(VLOOKUP(D12,Cadastro!$B$4:$H$100,2,FALSE),"") -> Enfermagem | F12: =IFERROR(VLOOKUP(D12,Cadastro!$B$4:$H$100,3,FALSE),"") -> R1 | G12: UBS Central | H12: Lidiane | I12: Prática | J12: 0.33333333 | K12: 0.70833333 | P12: =IF(OR(J12="",K12=""),0,(K12-J12)*24)+IF(OR(L12="",M12=""),0,(M12-L12)*24)+IF(OR(N12="",O12=""),0,(O12-N12)*24) -> 9 | Q12: =IF(OR(I12="Prática",I12="Teórico-prática"),P12,0) -> 9 | R12: =IF(OR(I12="Teórica",I12="Teórico-prática"),P12,0) -> 0
A13: 46091 | B13: =IF(A13="","",YEAR(A13)) -> 2026 | C13: =IF(A13="","",TEXT(A13,"mmmm")) -> março | D13: Daniely Kunrath | E13: =IFERROR(VLOOKUP(D13,Cadastro!$B$4:$H$100,2,FALSE),"") -> Enfermagem | F13: =IFERROR(VLOOKUP(D13,Cadastro!$B$4:$H$100,3,FALSE),"") -> R1 | G13: UBS Central | H13: Lidiane | I13: Prática | J13: 0.33333333 | K13: 0.70833333 | P13: =IF(OR(J13="",K13=""),0,(K13-J13)*24)+IF(OR(L13="",M13=""),0,(M13-L13)*24)+IF(OR(N13="",O13=""),0,(O13-N13)*24) -> 9 | Q13: =IF(OR(I13="Prática",I13="Teórico-prática"),P13,0) -> 9 | R13: =IF(OR(I13="Teórica",I13="Teórico-prática"),P13,0) -> 0
A14: 46092 | B14: =IF(A14="","",YEAR(A14)) -> 2026 | C14: =IF(A14="","",TEXT(A14,"mmmm")) -> março | D14: Daniely Kunrath | E14: =IFERROR(VLOOKUP(D14,Cadastro!$B$4:$H$100,2,FALSE),"") -> Enfermagem | F14: =IFERROR(VLOOKUP(D14,Cadastro!$B$4:$H$100,3,FALSE),"") -> R1 | G14: UBS Central | H14: Lidiane | I14: Prática | J14: 0.33333333 | K14: 0.70833333 | P14: =IF(OR(J14="",K14=""),0,(K14-J14)*24)+IF(OR(L14="",M14=""),0,(M14-L14)*24)+IF(OR(N14="",O14=""),0,(O14-N14)*24) -> 9 | Q14: =IF(OR(I14="Prática",I14="Teórico-prática"),P14,0) -> 9 | R14: =IF(OR(I14="Teórica",I14="Teórico-prática"),P14,0) -> 0
A15: 46093 | B15: =IF(A15="","",YEAR(A15)) -> 2026 | C15: =IF(A15="","",TEXT(A15,"mmmm")) -> março | D15: Daniely Kunrath | E15: =IFERROR(VLOOKUP(D15,Cadastro!$B$4:$H$100,2,FALSE),"") -> Enfermagem | F15: =IFERROR(VLOOKUP(D15,Cadastro!$B$4:$H$100,3,FALSE),"") -> R1 | G15: UBS Central | H15: Lidiane | I15: Prática | J15: 0.33333333 | K15: 0.70833333 | P15: =IF(OR(J15="",K15=""),0,(K15-J15)*24)+IF(OR(L15="",M15=""),0,(M15-L15)*24)+IF(OR(N15="",O15=""),0,(O15-N15)*24) -> 9 | Q15: =IF(OR(I15="Prática",I15="Teórico-prática"),P15,0) -> 9 | R15: =IF(OR(I15="Teórica",I15="Teórico-prática"),P15,0) -> 0
A16: 46094 | B16: =IF(A16="","",YEAR(A16)) -> 2026 | C16: =IF(A16="","",TEXT(A16,"mmmm")) -> março | D16: Daniely Kunrath | E16: =IFERROR(VLOOKUP(D16,Cadastro!$B$4:$H$100,2,FALSE),"") -> Enfermagem | F16: =IFERROR(VLOOKUP(D16,Cadastro!$B$4:$H$100,3,FALSE),"") -> R1 | G16: UBS Central | H16: Lidiane | I16: Prática | J16: 0.33333333 | K16: 0.70833333 | P16: =IF(OR(J16="",K16=""),0,(K16-J16)*24)+IF(OR(L16="",M16=""),0,(M16-L16)*24)+IF(OR(N16="",O16=""),0,(O16-N16)*24) -> 9 | Q16: =IF(OR(I16="Prática",I16="Teórico-prática"),P16,0) -> 9 | R16: =IF(OR(I16="Teórica",I16="Teórico-prática"),P16,0) -> 0
A17: 46095 | B17: =IF(A17="","",YEAR(A17)) -> 2026 | C17: =IF(A17="","",TEXT(A17,"mmmm")) -> março | D17: Daniely Kunrath | E17: =IFERROR(VLOOKUP(D17,Cadastro!$B$4:$H$100,2,FALSE),"") -> Enfermagem | F17: =IFERROR(VLOOKUP(D17,Cadastro!$B$4:$H$100,3,FALSE),"") -> R1 | G17: UBS Central | H17: Lidiane | I17: Prática | P17: =IF(OR(J17="",K17=""),0,(K17-J17)*24)+IF(OR(L17="",M17=""),0,(M17-L17)*24)+IF(OR(N17="",O17=""),0,(O17-N17)*24) -> 0 | Q17: =IF(OR(I17="Prática",I17="Teórico-prática"),P17,0) -> 0 | R17: =IF(OR(I17="Teórica",I17="Teórico-prática"),P17,0) -> 0
A18: 46096 | B18: =IF(A18="","",YEAR(A18)) -> 2026 | C18: =IF(A18="","",TEXT(A18,"mmmm")) -> março | D18: Daniely Kunrath | E18: =IFERROR(VLOOKUP(D18,Cadastro!$B$4:$H$100,2,FALSE),"") -> Enfermagem | F18: =IFERROR(VLOOKUP(D18,Cadastro!$B$4:$H$100,3,FALSE),"") -> R1 | G18: UBS Central | H18: Lidiane | I18: Prática | P18: =IF(OR(J18="",K18=""),0,(K18-J18)*24)+IF(OR(L18="",M18=""),0,(M18-L18)*24)+IF(OR(N18="",O18=""),0,(O18-N18)*24) -> 0 | Q18: =IF(OR(I18="Prática",I18="Teórico-prática"),P18,0) -> 0 | R18: =IF(OR(I18="Teórica",I18="Teórico-prática"),P18,0) -> 0
A19: 46097 | B19: =IF(A19="","",YEAR(A19)) -> 2026 | C19: =IF(A19="","",TEXT(A19,"mmmm")) -> março | D19: Daniely Kunrath | E19: =IFERROR(VLOOKUP(D19,Cadastro!$B$4:$H$100,2,FALSE),"") -> Enfermagem | F19: =IFERROR(VLOOKUP(D19,Cadastro!$B$4:$H$100,3,FALSE),"") -> R1 | G19: UBS Central | H19: Lidiane | I19: Prática | J19: 0.30486111 | K19: 0.51041667 | L19: 0.56180556 | M19: 0.72916667 | P19: =IF(OR(J19="",K19=""),0,(K19-J19)*24)+IF(OR(L19="",M19=""),0,(M19-L19)*24)+IF(OR(N19="",O19=""),0,(O19-N19)*24) -> 8.95 | Q19: =IF(OR(I19="Prática",I19="Teórico-prática"),P19,0) -> 8.95 | R19: =IF(OR(I19="Teórica",I19="Teórico-prática"),P19,0) -> 0
A20: 46098 | B20: =IF(A20="","",YEAR(A20)) -> 2026 | C20: =IF(A20="","",TEXT(A20,"mmmm")) -> março | D20: Daniely Kunrath | E20: =IFERROR(VLOOKUP(D20,Cadastro!$B$4:$H$100,2,FALSE),"") -> Enfermagem | F20: =IFERROR(VLOOKUP(D20,Cadastro!$B$4:$H$100,3,FALSE),"") -> R1 | G20: UBS Central | H20: Lidiane | I20: Prática | J20: 0.29166667 | K20: 0.50347222 | L20: 0.5625 | M20: 0.73611111 | N20: 0.75 | O20: 0.875 | P20: =IF(OR(J20="",K20=""),0,(K20-J20)*24)+IF(OR(L20="",M20=""),0,(M20-L20)*24)+IF(OR(N20="",O20=""),0,(O20-N20)*24) -> 12.25 | Q20: =IF(OR(I20="Prática",I20="Teórico-prática"),P20,0) -> 12.25 | R20: =IF(OR(I20="Teórica",I20="Teórico-prática"),P20,0) -> 0
A21: 46099 | B21: =IF(A21="","",YEAR(A21)) -> 2026 | C21: =IF(A21="","",TEXT(A21,"mmmm")) -> março | D21: Daniely Kunrath | E21: =IFERROR(VLOOKUP(D21,Cadastro!$B$4:$H$100,2,FALSE),"") -> Enfermagem | F21: =IFERROR(VLOOKUP(D21,Cadastro!$B$4:$H$100,3,FALSE),"") -> R1 | G21: UBS Central | H21: Lidiane | I21: Prática | J21: 0.29861111 | K21: 0.5 | L21: 0.56944444 | M21: 0.72916667 | P21: =IF(OR(J21="",K21=""),0,(K21-J21)*24)+IF(OR(L21="",M21=""),0,(M21-L21)*24)+IF(OR(N21="",O21=""),0,(O21-N21)*24) -> 8.6666667 | Q21: =IF(OR(I21="Prática",I21="Teórico-prática"),P21,0) -> 8.6666667 | R21: =IF(OR(I21="Teórica",I21="Teórico-prática"),P21,0) -> 0
A22: 46100 | B22: =IF(A22="","",YEAR(A22)) -> 2026 | C22: =IF(A22="","",TEXT(A22,"mmmm")) -> março | D22: Daniely Kunrath | E22: =IFERROR(VLOOKUP(D22,Cadastro!$B$4:$H$100,2,FALSE),"") -> Enfermagem | F22: =IFERROR(VLOOKUP(D22,Cadastro!$B$4:$H$100,3,FALSE),"") -> R1 | G22: UBS Central | H22: Lidiane | I22: Prática | J22: 0.29166667 | K22: 0.5 | L22: 0.5625 | M22: 0.72569444 | P22: =IF(OR(J22="",K22=""),0,(K22-J22)*24)+IF(OR(L22="",M22=""),0,(M22-L22)*24)+IF(OR(N22="",O22=""),0,(O22-N22)*24) -> 8.9166667 | Q22: =IF(OR(I22="Prática",I22="Teórico-prática"),P22,0) -> 8.9166667 | R22: =IF(OR(I22="Teórica",I22="Teórico-prática"),P22,0) -> 0
A23: 46101 | B23: =IF(A23="","",YEAR(A23)) -> 2026 | C23: =IF(A23="","",TEXT(A23,"mmmm")) -> março | D23: Daniely Kunrath | E23: =IFERROR(VLOOKUP(D23,Cadastro!$B$4:$H$100,2,FALSE),"") -> Enfermagem | F23: =IFERROR(VLOOKUP(D23,Cadastro!$B$4:$H$100,3,FALSE),"") -> R1 | G23: UBS Central | H23: Lidiane | I23: Prática | J23: 0.29513889 | K23: 0.5 | L23: 0.56597222 | M23: 0.72916667 | P23: =IF(OR(J23="",K23=""),0,(K23-J23)*24)+IF(OR(L23="",M23=""),0,(M23-L23)*24)+IF(OR(N23="",O23=""),0,(O23-N23)*24) -> 8.8333333 | Q23: =IF(OR(I23="Prática",I23="Teórico-prática"),P23,0) -> 8.8333333 | R23: =IF(OR(I23="Teórica",I23="Teórico-prática"),P23,0) -> 0
A24: 46102 | B24: =IF(A24="","",YEAR(A24)) -> 2026 | C24: =IF(A24="","",TEXT(A24,"mmmm")) -> março | D24: Daniely Kunrath | E24: =IFERROR(VLOOKUP(D24,Cadastro!$B$4:$H$100,2,FALSE),"") -> Enfermagem | F24: =IFERROR(VLOOKUP(D24,Cadastro!$B$4:$H$100,3,FALSE),"") -> R1 | G24: UBS Central | H24: Lidiane | I24: Prática | P24: =IF(OR(J24="",K24=""),0,(K24-J24)*24)+IF(OR(L24="",M24=""),0,(M24-L24)*24)+IF(OR(N24="",O24=""),0,(O24-N24)*24) -> 0 | Q24: =IF(OR(I24="Prática",I24="Teórico-prática"),P24,0) -> 0 | R24: =IF(OR(I24="Teórica",I24="Teórico-prática"),P24,0) -> 0
A25: 46103 | B25: =IF(A25="","",YEAR(A25)) -> 2026 | C25: =IF(A25="","",TEXT(A25,"mmmm")) -> março | D25: Daniely Kunrath | E25: =IFERROR(VLOOKUP(D25,Cadastro!$B$4:$H$100,2,FALSE),"") -> Enfermagem | F25: =IFERROR(VLOOKUP(D25,Cadastro!$B$4:$H$100,3,FALSE),"") -> R1 | G25: UBS Central | H25: Lidiane | I25: Prática | P25: =IF(OR(J25="",K25=""),0,(K25-J25)*24)+IF(OR(L25="",M25=""),0,(M25-L25)*24)+IF(OR(N25="",O25=""),0,(O25-N25)*24) -> 0 | Q25: =IF(OR(I25="Prática",I25="Teórico-prática"),P25,0) -> 0 | R25: =IF(OR(I25="Teórica",I25="Teórico-prática"),P25,0) -> 0
A26: 46104 | B26: =IF(A26="","",YEAR(A26)) -> 2026 | C26: =IF(A26="","",TEXT(A26,"mmmm")) -> março | D26: Daniely Kunrath | E26: =IFERROR(VLOOKUP(D26,Cadastro!$B$4:$H$100,2,FALSE),"") -> Enfermagem | F26: =IFERROR(VLOOKUP(D26,Cadastro!$B$4:$H$100,3,FALSE),"") -> R1 | G26: UBS Central | H26: Lidiane | I26: Prática | J26: 0.29166667 | K26: 0.5 | L26: 0.5625 | M26: 0.72916667 | P26: =IF(OR(J26="",K26=""),0,(K26-J26)*24)+IF(OR(L26="",M26=""),0,(M26-L26)*24)+IF(OR(N26="",O26=""),0,(O26-N26)*24) -> 9 | Q26: =IF(OR(I26="Prática",I26="Teórico-prática"),P26,0) -> 9 | R26: =IF(OR(I26="Teórica",I26="Teórico-prática"),P26,0) -> 0
A27: 46105 | B27: =IF(A27="","",YEAR(A27)) -> 2026 | C27: =IF(A27="","",TEXT(A27,"mmmm")) -> março | D27: Daniely Kunrath | E27: =IFERROR(VLOOKUP(D27,Cadastro!$B$4:$H$100,2,FALSE),"") -> Enfermagem | F27: =IFERROR(VLOOKUP(D27,Cadastro!$B$4:$H$100,3,FALSE),"") -> R1 | G27: UBS Central | H27: Lidiane | I27: Prática | J27: 0.28472222 | K27: 0.5 | L27: 0.57291667 | M27: 0.72916667 | N27: 0.75 | O27: 0.87152778 | P27: =IF(OR(J27="",K27=""),0,(K27-J27)*24)+IF(OR(L27="",M27=""),0,(M27-L27)*24)+IF(OR(N27="",O27=""),0,(O27-N27)*24) -> 11.833333 | Q27: =IF(OR(I27="Prática",I27="Teórico-prática"),P27,0) -> 11.833333 | R27: =IF(OR(I27="Teórica",I27="Teórico-prática"),P27,0) -> 0
A28: 46106 | B28: =IF(A28="","",YEAR(A28)) -> 2026 | C28: =IF(A28="","",TEXT(A28,"mmmm")) -> março | D28: Daniely Kunrath | E28: =IFERROR(VLOOKUP(D28,Cadastro!$B$4:$H$100,2,FALSE),"") -> Enfermagem | F28: =IFERROR(VLOOKUP(D28,Cadastro!$B$4:$H$100,3,FALSE),"") -> R1 | G28: UBS Central | H28: Lidiane | I28: Prática | J28: 0.30208333 | K28: 0.66458333 | P28: =IF(OR(J28="",K28=""),0,(K28-J28)*24)+IF(OR(L28="",M28=""),0,(M28-L28)*24)+IF(OR(N28="",O28=""),0,(O28-N28)*24) -> 8.7 | Q28: =IF(OR(I28="Prática",I28="Teórico-prática"),P28,0) -> 8.7 | R28: =IF(OR(I28="Teórica",I28="Teórico-prática"),P28,0) -> 0
A29: 46107 | B29: =IF(A29="","",YEAR(A29)) -> 2026 | C29: =IF(A29="","",TEXT(A29,"mmmm")) -> março | D29: Daniely Kunrath | E29: =IFERROR(VLOOKUP(D29,Cadastro!$B$4:$H$100,2,FALSE),"") -> Enfermagem | F29: =IFERROR(VLOOKUP(D29,Cadastro!$B$4:$H$100,3,FALSE),"") -> R1 | G29: UBS Central | H29: Lidiane | I29: Prática | J29: 0.29513889 | K29: 0.50416667 | L29: 0.56458333 | M29: 0.74305556 | P29: =IF(OR(J29="",K29=""),0,(K29-J29)*24)+IF(OR(L29="",M29=""),0,(M29-L29)*24)+IF(OR(N29="",O29=""),0,(O29-N29)*24) -> 9.3 | Q29: =IF(OR(I29="Prática",I29="Teórico-prática"),P29,0) -> 9.3 | R29: =IF(OR(I29="Teórica",I29="Teórico-prática"),P29,0) -> 0
A30: 46108 | B30: =IF(A30="","",YEAR(A30)) -> 2026 | C30: =IF(A30="","",TEXT(A30,"mmmm")) -> março | D30: Daniely Kunrath | E30: =IFERROR(VLOOKUP(D30,Cadastro!$B$4:$H$100,2,FALSE),"") -> Enfermagem | F30: =IFERROR(VLOOKUP(D30,Cadastro!$B$4:$H$100,3,FALSE),"") -> R1 | G30: UBS Central | H30: Lidiane | I30: Prática | J30: 0.28888889 | K30: 0.5 | L30: 0.5625 | M30: 0.73611111 | P30: =IF(OR(J30="",K30=""),0,(K30-J30)*24)+IF(OR(L30="",M30=""),0,(M30-L30)*24)+IF(OR(N30="",O30=""),0,(O30-N30)*24) -> 9.2333333 | Q30: =IF(OR(I30="Prática",I30="Teórico-prática"),P30,0) -> 9.2333333 | R30: =IF(OR(I30="Teórica",I30="Teórico-prática"),P30,0) -> 0
A31: 46109 | B31: =IF(A31="","",YEAR(A31)) -> 2026 | C31: =IF(A31="","",TEXT(A31,"mmmm")) -> março | D31: Daniely Kunrath | E31: =IFERROR(VLOOKUP(D31,Cadastro!$B$4:$H$100,2,FALSE),"") -> Enfermagem | F31: =IFERROR(VLOOKUP(D31,Cadastro!$B$4:$H$100,3,FALSE),"") -> R1 | G31: UBS Central | H31: Lidiane | I31: Prática | P31: =IF(OR(J31="",K31=""),0,(K31-J31)*24)+IF(OR(L31="",M31=""),0,(M31-L31)*24)+IF(OR(N31="",O31=""),0,(O31-N31)*24) -> 0 | Q31: =IF(OR(I31="Prática",I31="Teórico-prática"),P31,0) -> 0 | R31: =IF(OR(I31="Teórica",I31="Teórico-prática"),P31,0) -> 0
A32: 46110 | B32: =IF(A32="","",YEAR(A32)) -> 2026 | C32: =IF(A32="","",TEXT(A32,"mmmm")) -> março | D32: Daniely Kunrath | E32: =IFERROR(VLOOKUP(D32,Cadastro!$B$4:$H$100,2,FALSE),"") -> Enfermagem | F32: =IFERROR(VLOOKUP(D32,Cadastro!$B$4:$H$100,3,FALSE),"") -> R1 | G32: UBS Central | H32: Lidiane | I32: Prática | P32: =IF(OR(J32="",K32=""),0,(K32-J32)*24)+IF(OR(L32="",M32=""),0,(M32-L32)*24)+IF(OR(N32="",O32=""),0,(O32-N32)*24) -> 0 | Q32: =IF(OR(I32="Prática",I32="Teórico-prática"),P32,0) -> 0 | R32: =IF(OR(I32="Teórica",I32="Teórico-prática"),P32,0) -> 0
A33: 46111 | B33: =IF(A33="","",YEAR(A33)) -> 2026 | C33: =IF(A33="","",TEXT(A33,"mmmm")) -> março | D33: Daniely Kunrath | E33: =IFERROR(VLOOKUP(D33,Cadastro!$B$4:$H$100,2,FALSE),"") -> Enfermagem | F33: =IFERROR(VLOOKUP(D33,Cadastro!$B$4:$H$100,3,FALSE),"") -> R1 | G33: UBS Central | H33: Lidiane | I33: Prática | J33: 0.30208333 | K33: 0.50347222 | L33: 0.55972222 | M33: 0.72847222 | P33: =IF(OR(J33="",K33=""),0,(K33-J33)*24)+IF(OR(L33="",M33=""),0,(M33-L33)*24)+IF(OR(N33="",O33=""),0,(O33-N33)*24) -> 8.8833333 | Q33: =IF(OR(I33="Prática",I33="Teórico-prática"),P33,0) -> 8.8833333 | R33: =IF(OR(I33="Teórica",I33="Teórico-prática"),P33,0) -> 0
A34: 46112 | B34: =IF(A34="","",YEAR(A34)) -> 2026 | C34: =IF(A34="","",TEXT(A34,"mmmm")) -> março | D34: Daniely Kunrath | E34: =IFERROR(VLOOKUP(D34,Cadastro!$B$4:$H$100,2,FALSE),"") -> Enfermagem | F34: =IFERROR(VLOOKUP(D34,Cadastro!$B$4:$H$100,3,FALSE),"") -> R1 | G34: UBS Central | H34: Lidiane | I34: Prática | J34: 0.28472222 | K34: 0.5 | L34: 0.55555556 | M34: 0.73263889 | N34: 0.75 | O34: 0.86111111 | P34: =IF(OR(J34="",K34=""),0,(K34-J34)*24)+IF(OR(L34="",M34=""),0,(M34-L34)*24)+IF(OR(N34="",O34=""),0,(O34-N34)*24) -> 12.083333 | Q34: =IF(OR(I34="Prática",I34="Teórico-prática"),P34,0) -> 12.083333 | R34: =IF(OR(I34="Teórica",I34="Teórico-prática"),P34,0) -> 0
B35: =IF(A35="","",YEAR(A35)) | C35: =IF(A35="","",TEXT(A35,"mmmm")) | E35: =IFERROR(VLOOKUP(D35,Cadastro!$B$4:$H$100,2,FALSE),"") | F35: =IFERROR(VLOOKUP(D35,Cadastro!$B$4:$H$100,3,FALSE),"") | P35: =IF(OR(J35="",K35=""),0,(K35-J35)*24)+IF(OR(L35="",M35=""),0,(M35-L35)*24)+IF(OR(N35="",O35=""),0,(O35-N35)*24) -> 0 | Q35: =IF(OR(I35="Prática",I35="Teórico-prática"),P35,0) -> 0 | R35: =IF(OR(I35="Teórica",I35="Teórico-prática"),P35,0) -> 0
A36: 46082 | B36: =IF(A36="","",YEAR(A36)) -> 2026 | C36: =IF(A36="","",TEXT(A36,"mmmm")) -> março | D36: Betânia Pereira Pardinho | E36: =IFERROR(VLOOKUP(D36,Cadastro!$B$4:$H$100,2,FALSE),"") -> Enfermagem | F36: =IFERROR(VLOOKUP(D36,Cadastro!$B$4:$H$100,3,FALSE),"") -> R1 | G36: UBS Central | H36: Lidiane | I36: Prática | P36: =IF(OR(J36="",K36=""),0,(K36-J36)*24)+IF(OR(L36="",M36=""),0,(M36-L36)*24)+IF(OR(N36="",O36=""),0,(O36-N36)*24) -> 0 | Q36: =IF(OR(I36="Prática",I36="Teórico-prática"),P36,0) -> 0 | R36: =IF(OR(I36="Teórica",I36="Teórico-prática"),P36,0) -> 0
A37: 46083 | B37: =IF(A37="","",YEAR(A37)) -> 2026 | C37: =IF(A37="","",TEXT(A37,"mmmm")) -> março | D37: Betânia Pereira Pardinho | E37: =IFERROR(VLOOKUP(D37,Cadastro!$B$4:$H$100,2,FALSE),"") -> Enfermagem | F37: =IFERROR(VLOOKUP(D37,Cadastro!$B$4:$H$100,3,FALSE),"") -> R1 | G37: UBS Central | H37: Lidiane | I37: Prática | P37: =IF(OR(J37="",K37=""),0,(K37-J37)*24)+IF(OR(L37="",M37=""),0,(M37-L37)*24)+IF(OR(N37="",O37=""),0,(O37-N37)*24) -> 0 | Q37: =IF(OR(I37="Prática",I37="Teórico-prática"),P37,0) -> 0 | R37: =IF(OR(I37="Teórica",I37="Teórico-prática"),P37,0) -> 0
A38: 46084 | B38: =IF(A38="","",YEAR(A38)) -> 2026 | C38: =IF(A38="","",TEXT(A38,"mmmm")) -> março | D38: Betânia Pereira Pardinho | E38: =IFERROR(VLOOKUP(D38,Cadastro!$B$4:$H$100,2,FALSE),"") -> Enfermagem | F38: =IFERROR(VLOOKUP(D38,Cadastro!$B$4:$H$100,3,FALSE),"") -> R1 | G38: UBS Central | H38: Lidiane | I38: Prática | P38: =IF(OR(J38="",K38=""),0,(K38-J38)*24)+IF(OR(L38="",M38=""),0,(M38-L38)*24)+IF(OR(N38="",O38=""),0,(O38-N38)*24) -> 0 | Q38: =IF(OR(I38="Prática",I38="Teórico-prática"),P38,0) -> 0 | R38: =IF(OR(I38="Teórica",I38="Teórico-prática"),P38,0) -> 0
A39: 46085 | B39: =IF(A39="","",YEAR(A39)) -> 2026 | C39: =IF(A39="","",TEXT(A39,"mmmm")) -> março | D39: Betânia Pereira Pardinho | E39: =IFERROR(VLOOKUP(D39,Cadastro!$B$4:$H$100,2,FALSE),"") -> Enfermagem | F39: =IFERROR(VLOOKUP(D39,Cadastro!$B$4:$H$100,3,FALSE),"") -> R1 | G39: UBS Central | H39: Lidiane | I39: Prática | P39: =IF(OR(J39="",K39=""),0,(K39-J39)*24)+IF(OR(L39="",M39=""),0,(M39-L39)*24)+IF(OR(N39="",O39=""),0,(O39-N39)*24) -> 0 | Q39: =IF(OR(I39="Prática",I39="Teórico-prática"),P39,0) -> 0 | R39: =IF(OR(I39="Teórica",I39="Teórico-prática"),P39,0) -> 0
A40: 46086 | B40: =IF(A40="","",YEAR(A40)) -> 2026 | C40: =IF(A40="","",TEXT(A40,"mmmm")) -> março | D40: Betânia Pereira Pardinho | E40: =IFERROR(VLOOKUP(D40,Cadastro!$B$4:$H$100,2,FALSE),"") -> Enfermagem | F40: =IFERROR(VLOOKUP(D40,Cadastro!$B$4:$H$100,3,FALSE),"") -> R1 | G40: UBS Central | H40: Lidiane | I40: Prática | P40: =IF(OR(J40="",K40=""),0,(K40-J40)*24)+IF(OR(L40="",M40=""),0,(M40-L40)*24)+IF(OR(N40="",O40=""),0,(O40-N40)*24) -> 0 | Q40: =IF(OR(I40="Prática",I40="Teórico-prática"),P40,0) -> 0 | R40: =IF(OR(I40="Teórica",I40="Teórico-prática"),P40,0) -> 0
A41: 46087 | B41: =IF(A41="","",YEAR(A41)) -> 2026 | C41: =IF(A41="","",TEXT(A41,"mmmm")) -> março | D41: Betânia Pereira Pardinho | E41: =IFERROR(VLOOKUP(D41,Cadastro!$B$4:$H$100,2,FALSE),"") -> Enfermagem | F41: =IFERROR(VLOOKUP(D41,Cadastro!$B$4:$H$100,3,FALSE),"") -> R1 | G41: UBS Central | H41: Lidiane | I41: Prática | P41: =IF(OR(J41="",K41=""),0,(K41-J41)*24)+IF(OR(L41="",M41=""),0,(M41-L41)*24)+IF(OR(N41="",O41=""),0,(O41-N41)*24) -> 0 | Q41: =IF(OR(I41="Prática",I41="Teórico-prática"),P41,0) -> 0 | R41: =IF(OR(I41="Teórica",I41="Teórico-prática"),P41,0) -> 0
...

Sheet Dashboard
A1: DASHBOARD DA RESIDÊNCIA MULTIPROFISSIONAL
A3: Indicador | B3: Valor | D3: Residente | E3: Profissão | F3: Período | G3: Situação | H3: CH realizada | I3: CH prática | J3: CH teórica | K3: % anual | M3: Profissão | N3: Nº residentes
A4: Total de residentes | B4: =COUNTA(Cadastro!$B$4:$B$100) -> 9 | D4: =Cadastro!B4 -> Daniely Kunrath | E4: =Cadastro!C4 -> Enfermagem | F4: =Cadastro!D4 -> R1 | G4: =Cadastro!F4 -> ATIVO | H4: =IF(D4="","",SUMIF(Frequencia!$D:$D,D4,Frequencia!$P:$P)) -> 161.65 | I4: =IF(D4="","",SUMIF(Frequencia!$D:$D,D4,Frequencia!$Q:$Q)) -> 161.65 | J4: =IF(D4="","",SUMIF(Frequencia!$D:$D,D4,Frequencia!$R:$R)) -> 0 | K4: =IF(D4="","",H4/Configurações!$I$5) -> 0.056128472 | M4: Enfermagem | N4: =COUNTIF(Cadastro!$C$4:$C$100,M4) -> 2
A5: Ativos | B5: =COUNTIF(Cadastro!$F$4:$F$100,"ATIVO") -> 9 | D5: =Cadastro!B5 -> Betânia Pereira Pardinho | E5: =Cadastro!C5 -> Enfermagem | F5: =Cadastro!D5 -> R1 | G5: =Cadastro!F5 -> ATIVO | H5: =IF(D5="","",SUMIF(Frequencia!$D:$D,D5,Frequencia!$P:$P)) -> 156.48333 | I5: =IF(D5="","",SUMIF(Frequencia!$D:$D,D5,Frequencia!$Q:$Q)) -> 156.48333 | J5: =IF(D5="","",SUMIF(Frequencia!$D:$D,D5,Frequencia!$R:$R)) -> 0 | K5: =IF(D5="","",H5/Configurações!$I$5) -> 0.054334491 | M5: Farmácia | N5: =COUNTIF(Cadastro!$C$4:$C$100,M5) -> 1
A6: R1 | B6: =COUNTIF(Cadastro!$D$4:$D$100,"R1") -> 9 | D6: =Cadastro!B6 -> Paulo Fernandes Dos Santos | E6: =Cadastro!C6 -> Farmácia | F6: =Cadastro!D6 -> R1 | G6: =Cadastro!F6 -> ATIVO | H6: =IF(D6="","",SUMIF(Frequencia!$D:$D,D6,Frequencia!$P:$P)) -> 134.2 | I6: =IF(D6="","",SUMIF(Frequencia!$D:$D,D6,Frequencia!$Q:$Q)) -> 134.2 | J6: =IF(D6="","",SUMIF(Frequencia!$D:$D,D6,Frequencia!$R:$R)) -> 0 | K6: =IF(D6="","",H6/Configurações!$I$5) -> 0.046597222 | M6: Fisioterapia | N6: =COUNTIF(Cadastro!$C$4:$C$100,M6) -> 1
A7: R2 | B7: =COUNTIF(Cadastro!$D$4:$D$100,"R2") -> 0 | D7: =Cadastro!B7 -> Maria Neves Lopes Menezes | E7: =Cadastro!C7 -> Fisioterapia | F7: =Cadastro!D7 -> R1 | G7: =Cadastro!F7 -> ATIVO | H7: =IF(D7="","",SUMIF(Frequencia!$D:$D,D7,Frequencia!$P:$P)) -> #REF! | I7: =IF(D7="","",SUMIF(Frequencia!$D:$D,D7,Frequencia!$Q:$Q)) -> #REF! | J7: =IF(D7="","",SUMIF(Frequencia!$D:$D,D7,Frequencia!$R:$R)) -> 0 | K7: =IF(D7="","",H7/Configurações!$I$5) -> #REF! | M7: Nutrição | N7: =COUNTIF(Cadastro!$C$4:$C$100,M7) -> 1
A8: CH total do programa | B8: =Configurações!$I$4 -> 5760 | D8: =Cadastro!B8 -> Benedito Tales Santos Sousa | E8: =Cadastro!C8 -> Nutrição | F8: =Cadastro!D8 -> R1 | G8: =Cadastro!F8 -> ATIVO | H8: =IF(D8="","",SUMIF(Frequencia!$D:$D,D8,Frequencia!$P:$P)) -> 0 | I8: =IF(D8="","",SUMIF(Frequencia!$D:$D,D8,Frequencia!$Q:$Q)) -> 0 | J8: =IF(D8="","",SUMIF(Frequencia!$D:$D,D8,Frequencia!$R:$R)) -> 0 | K8: =IF(D8="","",H8/Configurações!$I$5) -> 0 | M8: Psicologia | N8: =COUNTIF(Cadastro!$C$4:$C$100,M8) -> 1
A9: CH anual | B9: =Configurações!$I$5 -> 2880 | D9: =Cadastro!B9 -> Andrea Raissa Bonfim Medeiros | E9: =Cadastro!C9 -> Odontologia | F9: =Cadastro!D9 -> R1 | G9: =Cadastro!F9 -> ATIVO | H9: =IF(D9="","",SUMIF(Frequencia!$D:$D,D9,Frequencia!$P:$P)) -> 0 | I9: =IF(D9="","",SUMIF(Frequencia!$D:$D,D9,Frequencia!$Q:$Q)) -> 0 | J9: =IF(D9="","",SUMIF(Frequencia!$D:$D,D9,Frequencia!$R:$R)) -> 0 | K9: =IF(D9="","",H9/Configurações!$I$5) -> 0 | M9: Assistente Social | N9: =COUNTIF(Cadastro!$C$4:$C$100,M9) -> 1
A10: Meta teórica anual | B10: =Configurações!$I$6 -> 576 | D10: =Cadastro!B10 -> Fabiana Martins Vieira | E10: =Cadastro!C10 -> Odontologia | F10: =Cadastro!D10 -> R1 | G10: =Cadastro!F10 -> ATIVO | H10: =IF(D10="","",SUMIF(Frequencia!$D:$D,D10,Frequencia!$P:$P)) -> 0 | I10: =IF(D10="","",SUMIF(Frequencia!$D:$D,D10,Frequencia!$Q:$Q)) -> 0 | J10: =IF(D10="","",SUMIF(Frequencia!$D:$D,D10,Frequencia!$R:$R)) -> 0 | K10: =IF(D10="","",H10/Configurações!$I$5) -> 0 | M10: Fonoaudiologia | N10: =COUNTIF(Cadastro!$C$4:$C$100,M10) -> 0
A11: Meta prática anual | B11: =Configurações!$I$7 -> 2304 | D11: =Cadastro!B11 -> Pamela Daniele De Sousa | E11: =Cadastro!C11 -> Psicologia | F11: =Cadastro!D11 -> R1 | G11: =Cadastro!F11 -> ATIVO | H11: =IF(D11="","",SUMIF(Frequencia!$D:$D,D11,Frequencia!$P:$P)) -> 0 | I11: =IF(D11="","",SUMIF(Frequencia!$D:$D,D11,Frequencia!$Q:$Q)) -> 0 | J11: =IF(D11="","",SUMIF(Frequencia!$D:$D,D11,Frequencia!$R:$R)) -> 0 | K11: =IF(D11="","",H11/Configurações!$I$5) -> 0 | M11: Odontologia | N11: =COUNTIF(Cadastro!$C$4:$C$100,M11) -> 2
D12: =Cadastro!B12 -> Marcia Sales Belfort | E12: =Cadastro!C12 -> Assistente Social | F12: =Cadastro!D12 -> R1 | G12: =Cadastro!F12 -> ATIVO | H12: =IF(D12="","",SUMIF(Frequencia!$D:$D,D12,Frequencia!$P:$P)) -> 0 | I12: =IF(D12="","",SUMIF(Frequencia!$D:$D,D12,Frequencia!$Q:$Q)) -> 0 | J12: =IF(D12="","",SUMIF(Frequencia!$D:$D,D12,Frequencia!$R:$R)) -> 0 | K12: =IF(D12="","",H12/Configurações!$I$5) -> 0
D13: =Cadastro!B13 -> 0 | E13: =Cadastro!C13 -> 0 | F13: =Cadastro!D13 -> 0 | G13: =Cadastro!F13 -> 0 | H13: =IF(D13="","",SUMIF(Frequencia!$D:$D,D13,Frequencia!$P:$P)) -> 0 | I13: =IF(D13="","",SUMIF(Frequencia!$D:$D,D13,Frequencia!$Q:$Q)) -> 0 | J13: =IF(D13="","",SUMIF(Frequencia!$D:$D,D13,Frequencia!$R:$R)) -> 0 | K13: =IF(D13="","",H13/Configurações!$I$5) -> 0
D14: =Cadastro!B14 -> 0 | E14: =Cadastro!C14 -> 0 | F14: =Cadastro!D14 -> 0 | G14: =Cadastro!F14 -> 0 | H14: =IF(D14="","",SUMIF(Frequencia!$D:$D,D14,Frequencia!$P:$P)) -> 0 | I14: =IF(D14="","",SUMIF(Frequencia!$D:$D,D14,Frequencia!$Q:$Q)) -> 0 | J14: =IF(D14="","",SUMIF(Frequencia!$D:$D,D14,Frequencia!$R:$R)) -> 0 | K14: =IF(D14="","",H14/Configurações!$I$5) -> 0
D15: =Cadastro!B15 -> 0 | E15: =Cadastro!C15 -> 0 | F15: =Cadastro!D15 -> 0 | G15: =Cadastro!F15 -> 0 | H15: =IF(D15="","",SUMIF(Frequencia!$D:$D,D15,Frequencia!$P:$P)) -> 0 | I15: =IF(D15="","",SUMIF(Frequencia!$D:$D,D15,Frequencia!$Q:$Q)) -> 0 | J15: =IF(D15="","",SUMIF(Frequencia!$D:$D,D15,Frequencia!$R:$R)) -> 0 | K15: =IF(D15="","",H15/Configurações!$I$5) -> 0
D16: =Cadastro!B16 -> 0 | E16: =Cadastro!C16 -> 0 | F16: =Cadastro!D16 -> 0 | G16: =Cadastro!F16 -> 0 | H16: =IF(D16="","",SUMIF(Frequencia!$D:$D,D16,Frequencia!$P:$P)) -> 0 | I16: =IF(D16="","",SUMIF(Frequencia!$D:$D,D16,Frequencia!$Q:$Q)) -> 0 | J16: =IF(D16="","",SUMIF(Frequencia!$D:$D,D16,Frequencia!$R:$R)) -> 0 | K16: =IF(D16="","",H16/Configurações!$I$5) -> 0
D17: =Cadastro!B17 -> 0 | E17: =Cadastro!C17 -> 0 | F17: =Cadastro!D17 -> 0 | G17: =Cadastro!F17 -> 0 | H17: =IF(D17="","",SUMIF(Frequencia!$D:$D,D17,Frequencia!$P:$P)) -> 0 | I17: =IF(D17="","",SUMIF(Frequencia!$D:$D,D17,Frequencia!$Q:$Q)) -> 0 | J17: =IF(D17="","",SUMIF(Frequencia!$D:$D,D17,Frequencia!$R:$R)) -> 0 | K17: =IF(D17="","",H17/Configurações!$I$5) -> 0
D18: =Cadastro!B18 -> 0 | E18: =Cadastro!C18 -> 0 | F18: =Cadastro!D18 -> 0 | G18: =Cadastro!F18 -> 0 | H18: =IF(D18="","",SUMIF(Frequencia!$D:$D,D18,Frequencia!$P:$P)) -> 0 | I18: =IF(D18="","",SUMIF(Frequencia!$D:$D,D18,Frequencia!$Q:$Q)) -> 0 | J18: =IF(D18="","",SUMIF(Frequencia!$D:$D,D18,Frequencia!$R:$R)) -> 0 | K18: =IF(D18="","",H18/Configurações!$I$5) -> 0
D19: =Cadastro!B19 -> 0 | E19: =Cadastro!C19 -> 0 | F19: =Cadastro!D19 -> 0 | G19: =Cadastro!F19 -> 0 | H19: =IF(D19="","",SUMIF(Frequencia!$D:$D,D19,Frequencia!$P:$P)) -> 0 | I19: =IF(D19="","",SUMIF(Frequencia!$D:$D,D19,Frequencia!$Q:$Q)) -> 0 | J19: =IF(D19="","",SUMIF(Frequencia!$D:$D,D19,Frequencia!$R:$R)) -> 0 | K19: =IF(D19="","",H19/Configurações!$I$5) -> 0
D20: =Cadastro!B20 -> 0 | E20: =Cadastro!C20 -> 0 | F20: =Cadastro!D20 -> 0 | G20: =Cadastro!F20 -> 0 | H20: =IF(D20="","",SUMIF(Frequencia!$D:$D,D20,Frequencia!$P:$P)) -> 0 | I20: =IF(D20="","",SUMIF(Frequencia!$D:$D,D20,Frequencia!$Q:$Q)) -> 0 | J20: =IF(D20="","",SUMIF(Frequencia!$D:$D,D20,Frequencia!$R:$R)) -> 0 | K20: =IF(D20="","",H20/Configurações!$I$5) -> 0
D21: =Cadastro!B21 -> 0 | E21: =Cadastro!C21 -> 0 | F21: =Cadastro!D21 -> 0 | G21: =Cadastro!F21 -> 0 | H21: =IF(D21="","",SUMIF(Frequencia!$D:$D,D21,Frequencia!$P:$P)) -> 0 | I21: =IF(D21="","",SUMIF(Frequencia!$D:$D,D21,Frequencia!$Q:$Q)) -> 0 | J21: =IF(D21="","",SUMIF(Frequencia!$D:$D,D21,Frequencia!$R:$R)) -> 0 | K21: =IF(D21="","",H21/Configurações!$I$5) -> 0
D22: =Cadastro!B22 -> 0 | E22: =Cadastro!C22 -> 0 | F22: =Cadastro!D22 -> 0 | G22: =Cadastro!F22 -> 0 | H22: =IF(D22="","",SUMIF(Frequencia!$D:$D,D22,Frequencia!$P:$P)) -> 0 | I22: =IF(D22="","",SUMIF(Frequencia!$D:$D,D22,Frequencia!$Q:$Q)) -> 0 | J22: =IF(D22="","",SUMIF(Frequencia!$D:$D,D22,Frequencia!$R:$R)) -> 0 | K22: =IF(D22="","",H22/Configurações!$I$5) -> 0
D23: =Cadastro!B23 -> 0 | E23: =Cadastro!C23 -> 0 | F23: =Cadastro!D23 -> 0 | G23: =Cadastro!F23 -> 0 | H23: =IF(D23="","",SUMIF(Frequencia!$D:$D,D23,Frequencia!$P:$P)) -> 0 | I23: =IF(D23="","",SUMIF(Frequencia!$D:$D,D23,Frequencia!$Q:$Q)) -> 0 | J23: =IF(D23="","",SUMIF(Frequencia!$D:$D,D23,Frequencia!$R:$R)) -> 0 | K23: =IF(D23="","",H23/Configurações!$I$5) -> 0
... D100: =Cadastro!B100 -> 0 | E100: =Cadastro!C100 -> 0 | F100: =Cadastro!D100 -> 0 | G100: =Cadastro!F100 -> 0 | H100: =IF(D100="","",SUMIF(Frequencia!$D:$D,D100,Frequencia!$P:$P)) -> 0 | I100: =IF(D100="","",SUMIF(Frequencia!$D:$D,D100,Frequencia!$Q:$Q)) -> 0 | J100: =IF(D100="","",SUMIF(Frequencia!$D:$D,D100,Frequencia!$R:$R)) -> 0 | K100: =IF(D100="","",H100/Configurações!$I$5) -> 0

Sheet Relatorio_Individual
A1: RELATÓRIO INDIVIDUAL DO RESIDENTE
A3: Selecione o residente:
A5: Indicador | B5: Valor
A6: Profissão | B6: =IFERROR(VLOOKUP($B$3,Cadastro!$B$4:$H$100,2,FALSE),"")
A7: Período | B7: =IFERROR(VLOOKUP($B$3,Cadastro!$B$4:$H$100,3,FALSE),"")
A8: Situação | B8: =IFERROR(VLOOKUP($B$3,Cadastro!$B$4:$H$100,5,FALSE),"")
A9: CH anual prevista | B9: =Configurações!$I$5 -> 2880
A10: Horas realizadas | B10: =SUMIF(Frequencia!$D:$D,$B$3,Frequencia!$P:$P) -> 0
A11: CH prática | B11: =SUMIF(Frequencia!$D:$D,$B$3,Frequencia!$Q:$Q) -> 0
A12: CH teórica | B12: =SUMIF(Frequencia!$D:$D,$B$3,Frequencia!$R:$R) -> 0
A13: Horas restantes | B13: =MAX(0,B9-B10) -> 2880
A14: % anual cumprido | B14: =IFERROR(B10/B9,0) -> 0
